<?xml version="1.0"?>
<robot xmlns:xacro="http://www.ros.org/wiki/xacro" name="rover">
    <xacro:property name="PI" value="3.14159"/>
    <xacro:property name="effort" value="30"/>
    <xacro:property name="velocity" value="1000"/>
   

    <xacro:macro name="inertia_wheel">
        <inertial>
            <origin xyz="0 0 0" rpy="0 0 0"/>
            <mass value="3"/>
            <inertia ixx="1" ixy="0" ixz="0" iyy="1" iyz="0" izz="1"/>
        </inertial>

    </xacro:macro>
    <xacro:macro name="base_plate">
        <inertial>
            <origin xyz="0 0 0" rpy="0 0 0"/>
            <mass value="20"/>
            <inertia ixx="1" ixy="0" ixz="0" iyy="1" iyz="0" izz="1"/>
        </inertial>

    </xacro:macro>
    <xacro:macro name="rocker">
        <inertial>
            <origin xyz="0 0 0" rpy="0 0 0"/>
            <mass value="10"/>
            <inertia ixx="1" ixy="0" ixz="0" iyy="1" iyz="0" izz="1"/>
        </inertial>

    </xacro:macro>
    <xacro:macro name="bogie">
        <inertial>
            <origin xyz="0 0 0" rpy="0 0 0"/>
            <mass value="9"/>
            <inertia ixx="1" ixy="0" ixz="0" iyy="1" iyz="0" izz="1"/>
        </inertial>

    </xacro:macro>

    
    
    

    
    <link name="base_link">

        <visual>
            <origin xyz="0.2 0.2 0.8" rpy="0 0 0"/>
            <geometry>
                <mesh filename="package://rover_description/meshes/Plate.STL" scale="0.01 0.01 0.01"/>
                

                
            </geometry>
        </visual>
        <collision>
            <origin xyz="0.2 0.2 0.8" rpy="0 0 0"/>
            <geometry>
                <mesh filename="package://rover_description/meshes/Plate.STL" scale="0.01 0.01 0.01"/>
                

                
            </geometry>
            
        </collision>
        <xacro:base_plate/>
    

    </link>
    
    <link name="slot_right">

        <visual>
            <origin xyz="-1.84 0.01 -0.3" rpy="${PI/2} 0 0"/>
            <geometry>
                <mesh filename="package://rover_description/meshes2/platform.STL" scale="0.0045 0.0045 0.0045"/>
                

                
            </geometry>
        </visual>
        <collision>
            <origin xyz="-1.84 0.01 -0.3" rpy="${PI/2} 0 0"/>
            <geometry>
                <mesh filename="package://rover_description/meshes2/platform.STL" scale="0.0045 0.0045 0.0045"/>
                

                
            </geometry>
            
        </collision>
        <xacro:base_plate/>
    

    </link>
    <link name="slot_left">

        <visual>
            <origin xyz="-1.84 -0.01 -0.3" rpy="${PI/2} 0 0"/>
            <geometry>
                <mesh filename="package://rover_description/meshes2/platform.STL" scale="0.0045 0.0045 0.0045"/>
                

                
            </geometry>
        </visual>
        <collision>
            <origin xyz="-1.84 -0.01 -0.3" rpy="${PI/2} 0 0"/>
            <geometry>
                <mesh filename="package://rover_description/meshes2/platform.STL" scale="0.0045 0.0045 0.0045"/>
                

                
            </geometry>
            
        </collision>
        <xacro:base_plate/>
    

    </link>
    <link name="diff_bar">

        <visual>
            <origin xyz="0.13 0.43 -0.9" rpy="${PI/2} -${PI/2} 0"/>
            <geometry>
                <mesh filename="package://rover_description/meshes2/differential.STL" scale="0.0045 0.0045 0.0045"/>
                

                
            </geometry>
        </visual>
        <collision>
            <origin xyz="0.13 0.43 -0.9" rpy="${PI/2} -${PI/2} 0"/>
            <geometry>
                <mesh filename="package://rover_description/meshes2/differential.STL" scale="0.0045 0.0045 0.0045"/>
                

                
            </geometry>
            
        </collision>
        <xacro:base_plate/>
    

    </link>
    <link name="tierod_right">

        <visual>
            <origin xyz="0 -0.05 0" rpy="0 -${PI} 0"/>
            <geometry>
                <mesh filename="package://rover_description/meshes2/tierod.STL" scale="0.0045 0.0045 0.0045"/>
                

                
            </geometry>
        </visual>
        <collision>
            <origin xyz="0 -0.05 0" rpy="0 -${PI} 0"/>
            <geometry>
                <mesh filename="package://rover_description/meshes2/tierod.STL" scale="0.0045 0.0045 0.0045"/>
                

                
            </geometry>
            
        </collision>
        <xacro:base_plate/>
    

    </link>
    <link name="tierod_left">

        <visual>
            <origin xyz="0 0 0" rpy="0 -${PI} 0"/>
            <geometry>
                <mesh filename="package://rover_description/meshes2/tierod.STL" scale="0.0045 0.0045 0.0045"/>
                

                
            </geometry>
        </visual>
        <collision>
            <origin xyz="0 0 0" rpy="0 -${PI} 0"/>
            <geometry>
                <mesh filename="package://rover_description/meshes2/tierod.STL" scale="0.0045 0.0045 0.0045"/>
                

                
            </geometry>
            
        </collision>
        <xacro:base_plate/>
    

    </link>
    <link name="rocker_right">

        <visual>
            <origin xyz="2.0 0 -0.66" rpy="${PI/2} 0 ${PI}"/>
            <geometry>
                <mesh filename="package://rover_description/meshes2/rocker.STL" scale="0.0045 0.0045 0.0045"/>
                

                
            </geometry>
        </visual>
        <collision>
            <origin xyz="2.0 0 -0.66" rpy="${PI/2} 0 ${PI}"/>
            <geometry>
                <mesh filename="package://rover_description/meshes2/rocker.STL" scale="0.0045 0.0045 0.0045"/>
                

                
            </geometry>
            
        </collision>
        <xacro:base_plate/>
    

    </link>
    <link name="rocker_left">

        <visual>
            <origin xyz="2.0 0.05 -0.66" rpy="${PI/2} 0 ${PI}"/>
            <geometry>
                <mesh filename="package://rover_description/meshes2/rocker.STL" scale="0.0045 0.0045 0.0045"/>
                

                
            </geometry>
        </visual>
        <collision>
            <origin xyz="2.0 0.05 -0.66" rpy="${PI/2} 0 ${PI}"/>
            <geometry>
                <mesh filename="package://rover_description/meshes2/rocker.STL" scale="0.0045 0.0045 0.0045"/>
                

                
            </geometry>
            
        </collision>
        <xacro:base_plate/>
    

    </link>
    <link name="bogie_right">

        <visual>
            <origin xyz="0.45 0 -0.48" rpy="${PI/2} 0 ${PI}"/>
            <geometry>
                <mesh filename="package://rover_description/meshes2/bogie.STL" scale="0.0045 0.0045 0.0045"/>
                

                
            </geometry>
        </visual>
        <collision>
            <origin xyz="0.45 0 -0.48" rpy="${PI/2} 0 ${PI}"/>
            <geometry>
                <mesh filename="package://rover_description/meshes2/bogie.STL" scale="0.0045 0.0045 0.0045"/>
                

                
            </geometry>
            
        </collision>
        <xacro:base_plate/>
    

    </link>
    <link name="bogie_left">

        <visual>
            <origin xyz="0.45 0 -0.48" rpy="${PI/2} 0 ${PI}"/>
            <geometry>
                <mesh filename="package://rover_description/meshes2/bogie.STL" scale="0.0045 0.0045 0.0045"/>
                

                
            </geometry>
        </visual>
        <collision>
            <origin xyz="0.45 0 -0.48" rpy="${PI/2} 0 ${PI}"/>
            <geometry>
                <mesh filename="package://rover_description/meshes2/bogie.STL" scale="0.0045 0.0045 0.0045"/>
                

                
            </geometry>
            
        </collision>
        <xacro:base_plate/>
    

    </link>
    <link name="wheel1">

        <visual>
            <origin xyz="-0.2 0 -0.2" rpy="${PI/2} 0 0"/>
            <geometry>
                <mesh filename="package://rover_description/meshes/Wheel.STL" scale="0.01 0.01 0.01"/>
                

                
            </geometry>
        </visual>
        <collision>
            <origin xyz="-0.2 0 -0.2" rpy="${PI/2} 0 0"/>
            <geometry>
                <mesh filename="package://rover_description/meshes/Wheel.STL" scale="0.01 0.01 0.01"/>
                

                
            </geometry>
            
        </collision>
        <xacro:inertia_wheel/>
    

    </link>
    <link name="wheel2">

        <visual>
            <origin xyz="-0.2 0 -0.2" rpy="${PI/2} 0 0"/>
            <geometry>
                <mesh filename="package://rover_description/meshes/Wheel.STL" scale="0.01 0.01 0.01"/>
                

                
            </geometry>
        </visual>
        <collision>
            <origin xyz="-0.2 0 -0.2" rpy="${PI/2} 0 0"/>
            <geometry>
                <mesh filename="package://rover_description/meshes/Wheel.STL" scale="0.01 0.01 0.01"/>
                

                
            </geometry>
            
        </collision>
        <xacro:inertia_wheel/>
    

    </link>
    <link name="wheel3">

        <visual>
            <origin xyz="-0.2 0 -0.2" rpy="${PI/2} 0 0"/>
            <geometry>
                <mesh filename="package://rover_description/meshes/Wheel.STL" scale="0.01 0.01 0.01"/>
                

                
            </geometry>
        </visual>
        <collision>
            <origin xyz="-0.2 0 -0.2" rpy="${PI/2} 0 0"/>
            <geometry>
                <mesh filename="package://rover_description/meshes/Wheel.STL" scale="0.01 0.01 0.01"/>
                

                
            </geometry>
            
        </collision>
        <xacro:inertia_wheel/>
    

    </link>
    <link name="wheel4">

        <visual>
            <origin xyz="-0.2 0 0.22" rpy="-${PI/2} 0 0"/>
            <geometry>
                <mesh filename="package://rover_description/meshes/Wheel.STL" scale="0.01 0.01 0.01"/>
                

                
            </geometry>
        </visual>
        <collision>
            <origin xyz="-0.2 0 0.22" rpy="-${PI/2} 0 0"/>
            <geometry>
                <mesh filename="package://rover_description/meshes/Wheel.STL" scale="0.01 0.01 0.01"/>
                

                
            </geometry>
            
        </collision>
        <xacro:inertia_wheel/>
    

    </link>
    <link name="wheel5">

        <visual>
            <origin xyz="-0.2 0 0.22" rpy="-${PI/2} 0 0"/>
            <geometry>
                <mesh filename="package://rover_description/meshes/Wheel.STL" scale="0.01 0.01 0.01"/>
                

                
            </geometry>
        </visual>
        <collision>
            <origin xyz="-0.2 0 0.22" rpy="-${PI/2} 0 0"/>
            <geometry>
                <mesh filename="package://rover_description/meshes/Wheel.STL" scale="0.01 0.01 0.01"/>
                

                
            </geometry>
            
        </collision>
        <xacro:inertia_wheel/>
    

    </link>
    <link name="wheel6">

        <visual>
            <origin xyz="-0.2 0 0.22" rpy="-${PI/2} 0 0"/>
            <geometry>
                <mesh filename="package://rover_description/meshes/Wheel.STL" scale="0.01 0.01 0.01"/>
                

                
            </geometry>
        </visual>
        <collision>
            <origin xyz="-0.2 0 0.22" rpy="-${PI/2} 0 0"/>
            <geometry>
                <mesh filename="package://rover_description/meshes/Wheel.STL" scale="0.01 0.01 0.01"/>
                

                
            </geometry>
            
        </collision>
        <xacro:inertia_wheel/>
    

    </link>
    
    
    


    <joint name="plate_to_slot_right" type="fixed">
        <parent link="base_link"/>
        <child link="slot_right"/>
        <origin rpy="0 0 0" xyz="1.15 0.2 0.8"/>
  
    </joint>
    <joint name="plate_to_slot_left" type="fixed">
        <parent link="base_link"/>
        <child link="slot_left"/>
        <origin rpy="0 0 0" xyz="1.15 1.23 0.8"/>
  
    </joint>
    <joint name="plate_differential" type="fixed">
        <parent link="base_link"/>
        <child link="diff_bar"/>
        <origin rpy="0 0 0" xyz="1.95 0.83 0.8"/>
  
    </joint>
    <joint name="rod_right" type="fixed">
        <parent link="diff_bar"/>
        <child link="tierod_right"/>
        <origin rpy="0 0 0" xyz="0.05 -0.7 -0.1"/>
  
    </joint>
    <joint name="rod_left" type="fixed">
        <parent link="diff_bar"/>
        <child link="tierod_left"/>
        <origin rpy="0 0 0" xyz="0.05 0.37 -0.1"/>
  
    </joint>
    <joint name="rocker_right_link" type="fixed">
        <parent link="tierod_right"/>
        <child link="rocker_right"/>
        <origin rpy="0 0 0" xyz="-0.89 0 0"/>
  
    </joint>
    <joint name="rocker_left_link" type="fixed">
        <parent link="tierod_left"/>
        <child link="rocker_left"/>
        <origin rpy="0 0 0" xyz="-0.89 0 0"/>
  
    </joint>
    <joint name="rocker_right_to_bogie" type="revolute">
        <parent link="rocker_right"/>
        <child link="bogie_right"/>
        <origin rpy="0 0 0" xyz="0.36 0 -0.2"/>
        <axis xyz="0 1 0"/>
        <limit lower="-${PI/2}" upper="${PI/2}" effort="${effort}" velocity="${velocity}"/>
  
    </joint>
    <joint name="rocker_left_to_bogie" type="revolute">
        <parent link="rocker_left"/>
        <child link="bogie_left"/>
        <origin rpy="0 0 0" xyz="0.36 0.05 -0.2"/>
        <axis xyz="0 1 0"/>
        <limit lower="-${PI/2}" upper="${PI/2}" effort="${effort}" velocity="${velocity}"/>
  
    </joint>
    <joint name="wheel1_joint" type="continuous">
        <parent link="rocker_right"/>
        <child link="wheel1"/>
        <origin rpy="0 0 0" xyz="-0.76 0 -0.55"/>
        <axis xyz="0 1 0"/>



    </joint>
    <joint name="wheel2_joint" type="continuous">
        <parent link="bogie_right"/>
        <child link="wheel2"/>
        <origin rpy="0 0 0" xyz="-0.41 0 -0.37"/>
        <axis xyz="0 1 0"/>



    </joint>
    <joint name="wheel3_joint" type="continuous">
        <parent link="bogie_right"/>
        <child link="wheel3"/>
        <origin rpy="0 0 0" xyz="0.35 0 -0.37"/>
        <axis xyz="0 1 0"/>



    </joint>
        <joint name="wheel4_joint" type="continuous">
        <parent link="rocker_left"/>
        <child link="wheel4"/>
        <origin rpy="0 0 0" xyz="-0.76 0 -0.55"/>
        <axis xyz="0 1 0"/>



    </joint>
    <joint name="wheel5_joint" type="continuous">
        <parent link="bogie_left"/>
        <child link="wheel5"/>
        <origin rpy="0 0 0" xyz="-0.41 0 -0.37"/>
        <axis xyz="0 1 0"/>



    </joint>
    <joint name="wheel6_joint" type="continuous">
        <parent link="bogie_left"/>
        <child link="wheel6"/>
        <origin rpy="0 0 0" xyz="0.35 0 -0.37"/>
        <axis xyz="0 1 0"/>



    </joint>
 


  
    








  <!-- Load the Gazebo ROS control plugin -->
    <gazebo>
    <plugin name="rover_diff_drive_controller" filename="libgazebo_ros_diff_drive.so">
    
        <rightJoint>wheel2_joint</rightJoint>
        <leftJoint>wheel5_joint</leftJoint>
  <!-- Right middle wheel joint -->
      <wheelSeparation>1</wheelSeparation> <!-- Distance between wheels -->
      <wheelRadius>0.2</wheelRadius> <!-- Radius of wheels -->
      <publishWheelJointState>true</publishWheelJointState>
      <legacyMode>false</legacyMode>
       <!-- Update rate for the controller -->
       <commandTopic>cmd_vel</commandTopic>
    

      <robotBaseFrame>base_link</robotBaseFrame> <!-- Base frame of the rover -->
    </plugin>
    </gazebo>

    <gazebo reference="base_link">
        <material>Gazebo/Orange</material>
    </gazebo>
    <gazebo reference="rocker_right">
        <material>Gazebo/Orange</material>
    </gazebo>
    <gazebo reference="rocker_left">
        <material>Gazebo/Orange</material>
    </gazebo>
    <gazebo reference="bogie_right">
        <material>Gazebo/Orange</material>
    </gazebo>
    <gazebo reference="bogie_left">
        <material>Gazebo/Orange</material>
    </gazebo>
    <gazebo reference="wheel1">
        <material>Gazebo/Orange</material>
    </gazebo>
    <gazebo reference="wheel2">
        <material>Gazebo/Orange</material>
    </gazebo>
    <gazebo reference="wheel3">
        <material>Gazebo/Orange</material>
    </gazebo>
    <gazebo reference="wheel4">
        <material>Gazebo/Orange</material>
    </gazebo>
    <gazebo reference="wheel5">
        <material>Gazebo/Orange</material>
    </gazebo>
    <gazebo reference="wheel6">
        <material>Gazebo/Orange</material>
    </gazebo>











    





    
    </robot>
    